<robot name="vr_hand_vhacd_right">
 <link name="base">
		<inertial>
      <origin xyz="0 0 0" rpy="0 0 0"/>
      <mass value="0.12" />
      <inertia ixx="9.46434e-06" ixy="0.0" ixz="0.0" iyy="1.22209e-05" iyz="-2.49433e-17" izz="1.71183e-05"/>
    </inertial>
	</link>

  <link name="palm">
    <inertial>
      <origin xyz="0 0 0" rpy="0 0 0"/>
      <mass value="0.12"/>
      <inertia ixx="9.46434e-06" ixy="0.0" ixz="0.0" iyy="1.22209e-05" iyz="-2.49433e-17" izz="1.71183e-05"/>
    </inertial>
    <visual>
      <origin xyz="0 0 0" rpy="0 0 0"/>
      <geometry>
        <mesh filename="meshes/palm.obj" scale="0.001 0.001 0.001"/>
      </geometry>
      <material name="palm_color">
        <color rgba="0.74902 0.74902 0.74902 1.0"/>
      </material>
    </visual>
    <collision>
      <origin xyz="0 0 0" rpy="0 0 0"/>
      <geometry>
        <mesh filename="vhacd_meshes/palm.obj" scale="0.001 0.001 0.001"/>
      </geometry>
    </collision>
  </link>

  <joint name="palm__base" type="fixed">
		<origin xyz="0 0 0" rpy="0 0 0"/>
		<parent link="base"/>
		<child link="palm"/>
  	</joint>
  
  <link name="Rproximal">
    <inertial>
      <origin xyz="-0.00506265498327 0.000178411167835 -0.0113952992502" rpy="0 0 0"/>
      <mass value="0.0046468"/>
      <inertia ixx="3.60659e-07" ixy="2.95375e-10" ixz="3.96643e-12" iyy="4.02251e-07" iyz="7.4602e-09" izz="1.59669e-07"/>
    </inertial>
    <visual>
      <origin xyz="0.00532660458173 -0.00134315858259 -0.0128298354943" rpy="0 0 0"/>
      <geometry>
        <mesh filename="meshes/seg_L.obj" scale="0.001 0.001 0.001"/>
      </geometry>
      <material name="Rproximal_color">
        <color rgba="0.74902 0.74902 0.74902 1.0"/>
      </material>
    </visual>
    <collision>
      <origin xyz="0.00532660458173 -0.00134315858259 -0.0128298354943" rpy="0 0 0"/>
      <geometry>
        <mesh filename="vhacd_meshes/seg_L.obj" scale="0.001 0.001 0.001"/>
      </geometry>
    </collision>
  </link>
  
  <joint name="Rproximal__palm" type="revolute">
    <origin xyz="0.017963 -0.079365 0.00148931" rpy="-1.83998062112 -0.070428847363 0.101332262919"/>
    <axis xyz="-1.00000007251 -8.46220030541e-08 1.44225053858e-07"/>
    <parent link="base"/>
    <child link="Rproximal"/>
    <limit effort="0.5" lower="0.0" upper="1.4835298642" velocity="1.0"/>
    <dynamics damping="0.1"/>
  </joint>
  
  <link name="Rmiddle">
    <inertial>
      <origin xyz="-0.0050627375168 0.000178703837342 -0.0113961050151" rpy="0 0 0"/>
      <mass value="0.0046468"/>
      <inertia ixx="3.60659e-07" ixy="2.95375e-10" ixz="3.96643e-12" iyy="4.02251e-07" iyz="7.4602e-09" izz="1.59669e-07"/>
    </inertial>
    <visual>
      <origin xyz="0.00532662722179 -0.00134303584663 -0.0128300831679" rpy="0 0 0"/>
      <geometry>
        <mesh filename="meshes/seg_finger_tip.obj" scale="0.001 0.001 0.001"/>
      </geometry>
      <material name="Rmiddle_color">
        <color rgba="0.74902 0.74902 0.74902 1.0"/>
      </material>
    </visual>
    <collision>
      <origin xyz="0.00532662722179 -0.00134303584663 -0.0128300831679" rpy="0 0 0"/>
      <geometry>
        <mesh filename="vhacd_meshes/seg_finger_tip.obj" scale="0.001 0.001 0.001"/>
      </geometry>
    </collision>
  </link>
  
  <joint name="Rmiddle__Rproximal" type="revolute">
    <origin xyz="0 0 -0.0258747809103" rpy="-0.0872670609142 0 2.76912342671e-07"/>
    <axis xyz="-1.00000007251 1.72767385245e-07 2.31542720386e-07"/>
    <parent link="Rproximal"/>
    <child link="Rmiddle"/>
    <limit effort="0.5" lower="0.0" upper="1.4835298642" velocity="1.0"/>
    <dynamics damping="0.1"/>
  </joint>
  
  <link name="Mproximal">
    <inertial>
      <origin xyz="-0.00506268032219 0.000178369758776 -0.0113951959251" rpy="0 0 0"/>
      <mass value="0.0046468"/>
      <inertia ixx="3.60659e-07" ixy="2.95375e-10" ixz="3.96643e-12" iyy="4.02251e-07" iyz="7.4602e-09" izz="1.59669e-07"/>
    </inertial>
    <visual>
      <origin xyz="0.00532660055243 -0.00134318776557 -0.0128295627043" rpy="0 0 0"/>
      <geometry>
        <mesh filename="meshes/seg_L.obj" scale="0.001 0.001 0.001"/>
      </geometry>
      <material name="Mproximal_color">
        <color rgba="0.74902 0.74902 0.74902 1.0"/>
      </material>
    </visual>
    <collision>
      <origin xyz="0.00532660055243 -0.00134318776557 -0.0128295627043" rpy="0 0 0"/>
      <geometry>
        <mesh filename="vhacd_meshes/seg_L.obj" scale="0.001 0.001 0.001"/>
      </geometry>
    </collision>
  </link>
  
  <joint name="Mproximal__palm" type="revolute">
    <origin xyz="-0.00678586 -0.080973 0.00076618" rpy="-1.83324870939 0.0859369188285 -0.0151906736407"/>
    <axis xyz="-1.00000030441 -5.71235363176e-07 2.22119205119e-07"/>
    <parent link="base"/>
    <child link="Mproximal"/>
    <limit effort="0.5" lower="0.0" upper="1.4835298642" velocity="1.0"/>
    <dynamics damping="0.1"/>
  </joint>
  
  <link name="Mmiddle">
    <inertial>
      <origin xyz="-0.00506269201108 0.000178473714736 -0.0113956264739" rpy="0 0 0"/>
      <mass value="0.0046468"/>
      <inertia ixx="3.60659e-07" ixy="2.95375e-10" ixz="3.96643e-12" iyy="4.02251e-07" iyz="7.4602e-09" izz="1.59669e-07"/>
    </inertial>
    <visual>
      <origin xyz="0.00532662940519 -0.001342939287 -0.012830098266" rpy="0 0 0"/>
      <geometry>
        <mesh filename="meshes/seg_finger_tip.obj" scale="0.001 0.001 0.001"/>
      </geometry>
      <material name="Mmiddle_color">
        <color rgba="0.74902 0.74902 0.74902 1.0"/>
      </material>
    </visual>
    <collision>
      <origin xyz="0.00532662940519 -0.001342939287 -0.012830098266" rpy="0 0 0"/>
      <geometry>
        <mesh filename="vhacd_meshes/seg_finger_tip.obj" scale="0.001 0.001 0.001"/>
      </geometry>
    </collision>
  </link>
  
  <joint name="Mmiddle__Mproximal" type="revolute">
    <origin xyz="0 -2.41651877793e-07 -0.0258742142625" rpy="-0.0872661749543 2.70259221066e-07 3.1679265362e-07"/>
    <axis xyz="-1.00000030441 -2.49278715942e-07 -7.0132973715e-08"/>
    <parent link="Mproximal"/>
    <child link="Mmiddle"/>
    <limit effort="0.5" lower="0.0" upper="1.4835298642" velocity="1.0"/>
    <dynamics damping="0.1"/>
  </joint>
  
  <link name="Pproximal">
    <inertial>
      <origin xyz="-0.00506265004772 0.000178471691603 -0.0113954440839" rpy="0 0 0"/>
      <mass value="0.0046468"/>
      <inertia ixx="3.60659e-07" ixy="2.95375e-10" ixz="3.96643e-12" iyy="4.02251e-07" iyz="7.4602e-09" izz="1.59669e-07"/>
    </inertial>
    <visual>
      <origin xyz="0.00532669695333 -0.00134327559708 -0.0128292006118" rpy="0 0 0"/>
      <geometry>
        <mesh filename="meshes/seg_L.obj" scale="0.001 0.001 0.001"/>
      </geometry>
      <material name="Pproximal_color">
        <color rgba="0.74902 0.74902 0.74902 1.0"/>
      </material>
    </visual>
    <collision>
      <origin xyz="0.00532669695333 -0.00134327559708 -0.0128292006118" rpy="0 0 0"/>
      <geometry>
        <mesh filename="vhacd_meshes/seg_L.obj" scale="0.001 0.001 0.001"/>
      </geometry>
    </collision>
  </link>
  
  <joint name="Pproximal__palm" type="revolute">
    <origin xyz="0.0426264 -0.070128 0.0038631" rpy="-1.86212856709 -0.138702648968 0.204065548896"/>
    <axis xyz="-0.999999718358 -2.63813422101e-07 -1.77932631934e-07"/>
    <parent link="base"/>
    <child link="Pproximal"/>
    <limit effort="0.5" lower="0.0" upper="1.4835298642" velocity="1.0"/>
    <dynamics damping="0.1"/>
  </joint>
  
  <link name="Pmiddle">
    <inertial>
      <origin xyz="-0.00506271792241 0.000178454269957 -0.0113956275282" rpy="0 0 0"/>
      <mass value="0.0046468"/>
      <inertia ixx="3.60659e-07" ixy="2.95375e-10" ixz="3.96643e-12" iyy="4.02251e-07" iyz="7.4602e-09" izz="1.59669e-07"/>
    </inertial>
    <visual>
      <origin xyz="0.00532646642137 -0.00134299429342 -0.0128302748856" rpy="0 0 0"/>
      <geometry>
        <mesh filename="meshes/seg_finger_tip.obj" scale="0.001 0.001 0.001"/>
      </geometry>
      <material name="Pmiddle_color">
        <color rgba="0.74902 0.74902 0.74902 1.0"/>
      </material>
    </visual>
    <collision>
      <origin xyz="0.00532646642137 -0.00134299429342 -0.0128302748856" rpy="0 0 0"/>
      <geometry>
        <mesh filename="vhacd_meshes/seg_finger_tip.obj" scale="0.001 0.001 0.001"/>
      </geometry>
    </collision>
  </link>
  
  <joint name="Pmiddle__Pproximal" type="revolute">
    <origin xyz="1.71429768873e-07 0 -0.0258743732015" rpy="-0.0872666026479 1.06320174575e-07 0"/>
    <axis xyz="-0.999999718358 -2.69819360882e-07 -3.08944752836e-07"/>
    <parent link="Pproximal"/>
    <child link="Pmiddle"/>
    <limit effort="0.5" lower="0.0" upper="1.4835298642" velocity="1.0"/>
    <dynamics damping="0.1"/>
  </joint>
  
  <link name="Tproximal">
    <inertial>
      <origin xyz="-0.00509118037371 -0.000108367330619 -0.00917567646424" rpy="0 0 0"/>
      <mass value="0.00379261"/>
      <inertia ixx="3.44891e-07" ixy="-5.85841e-09" ixz="-1.40349e-09" iyy="2.90581e-07" iyz="-9.57879e-09" izz="2.1814e-07"/>
    </inertial>
    <visual>
      <origin xyz="-0.00506247937312 1.51098425411e-07 -0.00864845498031" rpy="0 0 0"/>
      <geometry>
        <mesh filename="meshes/seg_M.obj" scale="0.001 0.001 0.001"/>
      </geometry>
      <material name="Tproximal_color">
        <color rgba="0.74902 0.74902 0.74902 1.0"/>
      </material>
    </visual>
    <collision>
      <origin xyz="-0.00506247937312 1.51098425411e-07 -0.00864845498031" rpy="0 0 0"/>
      <geometry>
        <mesh filename="vhacd_meshes/seg_M.obj" scale="0.001 0.001 0.001"/>
      </geometry>
    </collision>
  </link>
  
  <joint name="Tproximal__palm" type="revolute">
    <origin xyz="-0.041263 -0.024646 0.0157" rpy="-2.9762 0.36199 -2.4578"/>
    <axis xyz="-1.00000015905 4.04301755325e-07 -1.03967894405e-07"/>
    <parent link="base"/>
    <child link="Tproximal"/>
    <limit effort="0.5" lower="0.0" upper="1.57079632679" velocity="1.0"/>
    <dynamics damping="0.1"/>
  </joint>
  
  <link name="Tmiddle">
    <inertial>
      <origin xyz="-0.00509145714593 -0.000109508075581 -0.00917619264503" rpy="0 0 0"/>
      <mass value="0.00379261"/>
      <inertia ixx="3.44891e-07" ixy="-5.85841e-09" ixz="-1.40349e-09" iyy="2.90581e-07" iyz="-9.57879e-09" izz="2.1814e-07"/>
    </inertial>
    <visual>
      <origin xyz="-0.00506255005155 -3.30490933204e-07 -0.00864867274502" rpy="0 0 0"/>
      <geometry>
        <mesh filename="meshes/seg_thumb_tip.obj" scale="0.001 0.001 0.001"/>
      </geometry>
      <material name="Tmiddle_color">
        <color rgba="0.74902 0.74902 0.74902 1.0"/>
      </material>
    </visual>
    <collision>
      <origin xyz="-0.00506255005155 -3.30490933204e-07 -0.00864867274502" rpy="0 0 0"/>
      <geometry>
        <mesh filename="vhacd_meshes/seg_thumb_tip.obj" scale="0.001 0.001 0.001"/>
      </geometry>
    </collision>
  </link>
  
  <joint name="Tmiddle__Tproximal" type="revolute">
    <origin xyz="1.61327491782e-07 6.88063125837e-07 -0.0215856949813" rpy="-0.00953533375442 -2.2361018211e-07 -5.28725690007e-07"/>
    <axis xyz="-1.00000015905 -1.25559174474e-07 1.18450477621e-07"/>
    <parent link="Tproximal"/>
    <child link="Tmiddle"/>
    <limit effort="0.5" lower="0.0" upper="1.57079632679" velocity="1.0"/>
    <dynamics damping="0.1"/>
  </joint>

  <link name="Iproximal">
    <inertial>
      <origin xyz="-0.00506269303095 0.000178661194879 -0.0113960183486" rpy="0 0 0"/>
      <mass value="0.0046468"/>
      <inertia ixx="3.60659e-07" ixy="2.95375e-10" ixz="3.96643e-12" iyy="4.02251e-07" iyz="7.4602e-09" izz="1.59669e-07"/>
    </inertial>
    <visual>
      <origin xyz="0.00532665437356 -0.00134306865084 -0.0128298343462" rpy="0 0 0"/>
      <geometry>
        <mesh filename="meshes/seg_L.obj" scale="0.001 0.001 0.001"/>
      </geometry>
      <material name="Iproximal_color">
        <color rgba="0.74902 0.74902 0.74902 1.0"/>
      </material>
    </visual>
    <collision>
      <origin xyz="0.00532665437356 -0.00134306865084 -0.0128298343462" rpy="0 0 0"/>
      <geometry>
        <mesh filename="vhacd_meshes/seg_L.obj" scale="0.001 0.001 0.001"/>
      </geometry>
    </collision>
  </link>
  
  <joint name="Iproximal__palm" type="revolute">
    <origin xyz="-0.0318425 -0.079883 0.00351788" rpy="-1.84942615384 0.155854888307 -0.117563434836"/>
    <axis xyz="-0.999999806433 -3.11064646163e-07 -1.92575397934e-07"/>
    <parent link="base"/>
    <child link="Iproximal"/>
    <limit effort="0.5" lower="0.0" upper="1.4835298642" velocity="1.0"/>
    <dynamics damping="0.1"/>
  </joint>
  
  <link name="Imiddle">
    <inertial>
      <origin xyz="-0.00506266070615 0.000178528721729 -0.0113957955067" rpy="0 0 0"/>
      <mass value="0.0046468"/>
      <inertia ixx="3.60659e-07" ixy="2.95375e-10" ixz="3.96643e-12" iyy="4.02251e-07" iyz="7.4602e-09" izz="1.59669e-07"/>
    </inertial>
    <visual>
      <origin xyz="0.00532665674393 -0.00134322760034 -0.012829627881" rpy="0 0 0"/>
      <geometry>
        <mesh filename="meshes/seg_finger_tip.obj" scale="0.001 0.001 0.001"/>
      </geometry>
      <material name="Imiddle_color">
        <color rgba="0.74902 0.74902 0.74902 1.0"/>
      </material>
    </visual>
    <collision>
      <origin xyz="0.00532665674393 -0.00134322760034 -0.012829627881" rpy="0 0 0"/>
      <geometry>
        <mesh filename="vhacd_meshes/seg_finger_tip.obj" scale="0.001 0.001 0.001"/>
      </geometry>
    </collision>
  </link>
  
  <joint name="Imiddle__Iproximal" type="revolute">
    <origin xyz="0 0 -0.0258750517122" rpy="-0.0872662181335 -6.1944905734e-07 4.44119679405e-07"/>
    <axis xyz="-0.999999806433 9.5344259203e-08 4.3684563622e-07"/>
    <parent link="Iproximal"/>
    <child link="Imiddle"/>
    <limit effort="0.5" lower="0.0" upper="1.4835298642" velocity="1.0"/>
    <dynamics damping="0.1"/>
  </joint>
</robot>

