<?xml version="1.0" ?>
<robot name="urdf_door">
 <link name="world"/>
  <joint name="fixed" type="fixed">
    <parent link="world"/>
    <child link="baseLink"/>
    <origin xyz="0 0 0"/>
  </joint>

  <link name="baseLink">
    <inertial>
      <origin rpy="0 0 0" xyz="0 0 0"/>
       <mass value="10.0"/>
       <inertia ixx="0.1" ixy="0" ixz="0" iyy="0.1" iyz="0" izz="0.1"/>
    </inertial>
    <visual>
        <origin xyz='0 0 0' rpy='1.5707963267948966 0 0'/>
    <geometry>
     <mesh filename="door/processed2_055_frame.obj"  scale="0.01 0.01 0.01" />
    </geometry>
    <material name="brown">
        <color rgba="0.545 0.270 0.074 1"/>
    </material>
    </visual>
    <collision>
        <origin xyz='0 0 0' rpy='1.5707963267948966 0 0'/>
    <geometry>
     <mesh filename="door/055_frame_vhacd.obj"  scale="0.01 0.01 0.01" />
    </geometry>
    <material name="brown">
        <color rgba="0.545 0.270 0.074 1"/>
    </material>
    </collision>

  </link>
   <link name="childA">
    <inertial>
      <origin rpy="0 0 0" xyz="0 0 0"/>
      <mass value="80.0"/>
      <inertia ixx="0.048966669" ixy="0" ixz="0" iyy="0.046466667" iyz="0" izz="0.0041666669"/>
    </inertial>

    <visual>
    <origin xyz='0.45 0.02 0' rpy='1.5707963267948966 0 0'/>
    <geometry>
     <mesh filename="door/processed2_055_door.obj"  scale="0.01 0.01 0.01" />

    </geometry>
    <material name="brown">
        <color rgba="0.545 0.270 0.074 1"/>
    </material>

	</visual>
    <collision>
    <origin xyz='0.45 0.02 0' rpy='1.5707963267948966 0 0'/>
    <geometry>
     <mesh filename="door/055_door.obj"  scale="0.01 0.01 0.01" />
    </geometry>
    <material name="brown">
        <color rgba="0.545 0.270 0.074 1"/>
    </material>

    </collision>

   </link>


   <link name="knob">
    <inertial>
      <mass value="0.1"/>
      <inertia ixx="0.0" ixy="0" ixz="0" iyy="0.0" iyz="0" izz="0.0"/>
    </inertial>

    <visual>
    <geometry>
     <mesh filename="door/processed_055_knob_centered.obj"  scale="0.01 0.01 0.01" />

    </geometry>
    <material name="black">
        <color rgba="0.0 0.0 0.0 1"/>
    </material>

  </visual>
    <collision>
    <geometry>
     <mesh filename="door/processed_055_knob_centered.obj"  scale="0.01 0.01 0.01" />
    </geometry>
    <material name="black">
        <color rgba="0.0 0.0 0.0 1"/>
    </material>
    </collision>
   </link>



   <joint name="joint_baseLink_childA" type="revolute">
    <parent link="baseLink"/>
    <child link="childA"/>
	<dynamics damping="1000" friction="0"/>
    <origin xyz="-0.45 -0.04 0"/>
    <axis xyz="0 0 1"/>
    <limit lower="0" upper="1.7" />
  </joint>


  <joint name="door_to_knob" type="fixed">
  <parent link="childA"/>
  <child link="knob"/>
  <origin xyz="0.78 0.02 0.8" rpy="1.57 0 0"/>
  </joint>


</robot>

